Workbook

Sheet Summary
A1: Cyberneom Web — Regression Testing Checklist
A2: Version: | B2: 3.0.0+27
A3: URL: | B3: https://cyberneom-edd2d.web.app
A4: Tester(s):
A5: Fecha inicio:
A6: Fecha fin:
A8: KPI | B8: Valor
A9: Total de casos | B9: =COUNTA('Test Cases'!A2:A160)
A10: Passed | B10: =COUNTIF('Test Cases'!F2:F160,"Passed")
A11: Failed | B11: =COUNTIF('Test Cases'!F2:F160,"Failed")
A12: Blocked | B12: =COUNTIF('Test Cases'!F2:F160,"Blocked")
A13: Skipped | B13: =COUNTIF('Test Cases'!F2:F160,"Skipped")
A14: Not Run | B14: =COUNTIF('Test Cases'!F2:F160,"Not Run")
A15: % Cobertura | B15: =IFERROR((B10+B11+B12+B13)/B9,0)
A16: % Pass rate | B16: =IFERROR(B10/(B10+B11),0)
A18: Prioridad | B18: Total | C18: Passed | D18: Failed | E18: Pendientes
A19: P0 | B19: =COUNTIF('Test Cases'!D2:D160,"P0") | C19: =COUNTIFS('Test Cases'!D2:D160,"P0",'Test Cases'!F2:F160,"Passed") | D19: =COUNTIFS('Test Cases'!D2:D160,"P0",'Test Cases'!F2:F160,"Failed") | E19: =COUNTIFS('Test Cases'!D2:D160,"P0",'Test Cases'!F2:F160,"Not Run")
A20: P1 | B20: =COUNTIF('Test Cases'!D2:D160,"P1") | C20: =COUNTIFS('Test Cases'!D2:D160,"P1",'Test Cases'!F2:F160,"Passed") | D20: =COUNTIFS('Test Cases'!D2:D160,"P1",'Test Cases'!F2:F160,"Failed") | E20: =COUNTIFS('Test Cases'!D2:D160,"P1",'Test Cases'!F2:F160,"Not Run")
A21: P2 | B21: =COUNTIF('Test Cases'!D2:D160,"P2") | C21: =COUNTIFS('Test Cases'!D2:D160,"P2",'Test Cases'!F2:F160,"Passed") | D21: =COUNTIFS('Test Cases'!D2:D160,"P2",'Test Cases'!F2:F160,"Failed") | E21: =COUNTIFS('Test Cases'!D2:D160,"P2",'Test Cases'!F2:F160,"Not Run")
A22: P3 | B22: =COUNTIF('Test Cases'!D2:D160,"P3") | C22: =COUNTIFS('Test Cases'!D2:D160,"P3",'Test Cases'!F2:F160,"Passed") | D22: =COUNTIFS('Test Cases'!D2:D160,"P3",'Test Cases'!F2:F160,"Failed") | E22: =COUNTIFS('Test Cases'!D2:D160,"P3",'Test Cases'!F2:F160,"Not Run")

Sheet Test Cases
A1: Code | B1: Module | C1: Area | D1: Priority | E1: Title | F1: Status | G1: X (done) | H1: Tester | I1: Date | J1: Comment | K1: Defect ID | L1: Preconditions | M1: Steps | N1: Expected | O1: Platform Note
A2: SMK-01 | B2: neom_commons | C2: Smoke | D2: P0 | E2: Cold boot web | F2: Not Run | L2: Browser limpio | M2: Abrir landing | N2: Carga < 5s
A3: SMK-02 | B3: neom_commons | C3: Smoke | D3: P0 | E3: Cold boot android | F3: Not Run | L3: APK | M3: Lanzar | N3: OK
A4: SMK-03 | B4: neom_commons | C4: Smoke | D4: P0 | E4: Cold boot iOS | F4: Not Run | L4: TestFlight | M4: Lanzar | N4: OK
A5: SMK-04 | B5: neom_commons | C5: Smoke | D5: P0 | E5: Drawer principal | F5: Not Run | L5: Login | M5: Abrir drawer | N5: Items navegan
A6: SMK-05 | B6: neom_commons | C6: Smoke | D6: P1 | E6: Sin errores consola | F6: Not Run | L6: Cualquier | M6: F12 | N6: Sin rojos
A7: SMK-06 | B7: neom_commons | C7: Smoke | D7: P1 | E7: Web manifest | F7: Not Run | L7: Web | M7: DevTools > Application | N7: Manifest OK
A8: SMK-07 | B8: neom_commons | C8: Smoke | D8: P0 | E8: Firebase init | F8: Not Run | L8: Boot | M8: Logs | N8: Sin duplicate app
A9: AUTH-01 | B9: neom_auth | C9: Auth | D9: P0 | E9: Login email | F9: Not Run | L9: Cuenta test | M9: Email + pwd | N9: Home
A10: AUTH-02 | B10: neom_auth | C10: Auth | D10: P0 | E10: Login Google | F10: Not Run | L10: Cuenta Google | M10: Sign-in | N10: OK
A11: AUTH-03 | B11: neom_auth | C11: Auth | D11: P0 | E11: Login Apple | F11: Not Run | L11: Cuenta Apple | M11: Sign-in | N11: OK | O11: ⚠ Web-limited
A12: AUTH-04 | B12: neom_auth | C12: Auth | D12: P0 | E12: Logout | F12: Not Run | L12: Sesión | M12: Drawer > Logout | N12: Landing
A13: AUTH-05 | B13: neom_auth | C13: Auth | D13: P1 | E13: Recuperar password | F13: Not Run | L13: Email | M13: Forgot | N13: Email reset
A14: AUTH-06 | B14: neom_auth | C14: Auth | D14: P1 | E14: Persistencia sesión | F14: Not Run | L14: Login | M14: Cerrar/abrir | N14: Sigue
A15: ONB-01 | B15: neom_onboarding | C15: Onboarding | D15: P0 | E15: Flujo primer uso | F15: Not Run | L15: Cuenta nueva | M15: Completar | N15: Llega Home
A16: ONB-02 | B16: neom_onboarding | C16: Onboarding | D16: P1 | E16: Selección rol | F16: Not Run | L16: Onboarding | M16: Pick rol | N16: Guardado
A17: ONB-03 | B17: neom_onboarding | C17: Onboarding | D17: P2 | E17: Skip pasos | F17: Not Run | L17: Onboarding | M17: Skip | N17: Continúa
A18: PAR-01 | B18: neom_par | C18: PAR | D18: P0 | E18: Home PAR | F18: Not Run | L18: Login | M18: /par | N18: Dashboard cognitive fitness
A19: PAR-02 | B19: neom_par | C19: PAR | D19: P0 | E19: Readiness assessment | F19: Not Run | L19: PAR home | M19: /par/readiness | N19: Mic CV 60s arranca
A20: PAR-03 | B20: neom_par | C20: PAR | D20: P0 | E20: Mic CV calibración | F20: Not Run | L20: Readiness | M20: Hablar 60s | N20: CV calculado
A21: PAR-04 | B21: neom_par | C21: PAR | D21: P0 | E21: Score readiness | F21: Not Run | L21: CV calculado | M21: Ver | N21: Score 0-100 + percentil
A22: PAR-05 | B22: neom_par | C22: PAR | D22: P1 | E22: Protocolo táctico 1 | F22: Not Run | L22: PAR home | M22: /par/protocol/1 | N22: Carga + steps
A23: PAR-06 | B23: neom_par | C23: PAR | D23: P1 | E23: Protocolo táctico 2 | F23: Not Run | L23: PAR home | M23: /par/protocol/2 | N23: Carga + steps
... A27: PAR-10 | B27: neom_par | C27: PAR | D27: P2 | E27: Report PNG export | F27: Not Run | L27: Sesión | M27: Share | N27: Imagen generada
A28: PAR-11 | B28: neom_par | C28: PAR | D28: P2 | E28: DeskSensor background | F28: Not Run | L28: Desktop | M28: Habilitar | N28: Monitoreo silencioso | O28: 🚫 Web-excluded
A29: PAR-12 | B29: neom_par | C29: PAR | D29: P2 | E29: Persistencia sesiones | F29: Not Run | L29: 2 sesiones | M29: Reiniciar | N29: Ambas siguen
A30: BIO-01 | B30: neom_biofeedback | C30: Biofeedback | D30: P0 | E30: Permiso mic | F30: Not Run | L30: Primera vez | M30: Trigger | N30: Pide permiso
A31: BIO-02 | B31: neom_biofeedback | C31: Biofeedback | D31: P0 | E31: Breath detector | F31: Not Run | L31: Mic OK | M31: Respirar 30s | N31: Detecta ciclos
A32: BIO-03 | B32: neom_biofeedback | C32: Biofeedback | D32: P0 | E32: Movement detector | F32: Not Run | L32: Mic OK | M32: Hablar/moverse | N32: Eventos
A33: BIO-04 | B33: neom_biofeedback | C33: Biofeedback | D33: P1 | E33: HSS calculator | F33: Not Run | L33: Datos | M33: Computar | N33: S_r × e^(-γ × I_m)
A34: BIO-05 | B34: neom_biofeedback | C34: Biofeedback | D34: P1 | E34: Provider interface | F34: Not Run | L34: Mic provider | M34: Inject | N34: Funciona como API
A35: BIO-06 | B35: neom_biofeedback | C35: Biofeedback | D35: P2 | E35: Calibración ruido | F35: Not Run | L35: Ambiente nuevo | M35: Calibrar | N35: Baseline OK
A36: BIO-07 | B36: neom_biofeedback | C36: Biofeedback | D36: P2 | E36: Butterworth filter | F36: Not Run | L36: Audio raw | M36: Procesar | N36: 100-1200Hz pasa
A37: HST-01 | B37: neom_historic_state | C37: HistoricState | D37: P0 | E37: Iniciar sesión | F37: Not Run | L37: Login | M37: /historicState | N37: UI carga
A38: HST-02 | B38: neom_historic_state | C38: HistoricState | D38: P0 | E38: Fase 1 Anchor | F38: Not Run | L38: Sesión | M38: Iniciar | N38: 10Hz mantiene
A39: HST-03 | B39: neom_historic_state | C39: HistoricState | D39: P0 | E39: Fase 2 Diffusion | F39: Not Run | L39: Anchor OK | M39: Continuar | N39: Desciende a ~8.5Hz
A40: HST-04 | B40: neom_historic_state | C40: HistoricState | D40: P0 | E40: Fase 3 ExistentialBase | F40: Not Run | L40: Diffusion OK | M40: Continuar | N40: Llega 7.5Hz
... A52: STA-03 | B52: neom_states | C52: States | D52: P2 | E52: Histórico states | F52: Not Run | L52: Multiple | M52: Ver | N52: Línea temporal
A53: VR-01 | B53: neom_vr | C53: VR | D53: P2 | E53: Catálogo VR | F53: Not Run | L53: Login | M53: Drawer > VR | N53: Lista experiencias | O53: ⚠ Web-limited
A54: VR-02 | B54: neom_vr | C54: VR | D54: P2 | E54: Iniciar experiencia | F54: Not Run | L54: VR | M54: Start | N54: Carga 360° | O54: ⚠ Web-limited
...

Sheet By Module
A1: Module | B1: Total | C1: Passed | D1: Failed | E1: Blocked | F1: Skipped | G1: Not Run | H1: % Pass
A2: neom_admin | B2: =COUNTIF('Test Cases'!B2:B160,A2) | C2: =COUNTIFS('Test Cases'!B2:B160,A2,'Test Cases'!F2:F160,"Passed") | D2: =COUNTIFS('Test Cases'!B2:B160,A2,'Test Cases'!F2:F160,"Failed") | E2: =COUNTIFS('Test Cases'!B2:B160,A2,'Test Cases'!F2:F160,"Blocked") | F2: =COUNTIFS('Test Cases'!B2:B160,A2,'Test Cases'!F2:F160,"Skipped") | G2: =COUNTIFS('Test Cases'!B2:B160,A2,'Test Cases'!F2:F160,"Not Run") | H2: =IFERROR(C2/(C2+D2),0)
A3: neom_audio_player | B3: =COUNTIF('Test Cases'!B2:B160,A3) | C3: =COUNTIFS('Test Cases'!B2:B160,A3,'Test Cases'!F2:F160,"Passed") | D3: =COUNTIFS('Test Cases'!B2:B160,A3,'Test Cases'!F2:F160,"Failed") | E3: =COUNTIFS('Test Cases'!B2:B160,A3,'Test Cases'!F2:F160,"Blocked") | F3: =COUNTIFS('Test Cases'!B2:B160,A3,'Test Cases'!F2:F160,"Skipped") | G3: =COUNTIFS('Test Cases'!B2:B160,A3,'Test Cases'!F2:F160,"Not Run") | H3: =IFERROR(C3/(C3+D3),0)
A4: neom_auth | B4: =COUNTIF('Test Cases'!B2:B160,A4) | C4: =COUNTIFS('Test Cases'!B2:B160,A4,'Test Cases'!F2:F160,"Passed") | D4: =COUNTIFS('Test Cases'!B2:B160,A4,'Test Cases'!F2:F160,"Failed") | E4: =COUNTIFS('Test Cases'!B2:B160,A4,'Test Cases'!F2:F160,"Blocked") | F4: =COUNTIFS('Test Cases'!B2:B160,A4,'Test Cases'!F2:F160,"Skipped") | G4: =COUNTIFS('Test Cases'!B2:B160,A4,'Test Cases'!F2:F160,"Not Run") | H4: =IFERROR(C4/(C4+D4),0)
A5: neom_bank | B5: =COUNTIF('Test Cases'!B2:B160,A5) | C5: =COUNTIFS('Test Cases'!B2:B160,A5,'Test Cases'!F2:F160,"Passed") | D5: =COUNTIFS('Test Cases'!B2:B160,A5,'Test Cases'!F2:F160,"Failed") | E5: =COUNTIFS('Test Cases'!B2:B160,A5,'Test Cases'!F2:F160,"Blocked") | F5: =COUNTIFS('Test Cases'!B2:B160,A5,'Test Cases'!F2:F160,"Skipped") | G5: =COUNTIFS('Test Cases'!B2:B160,A5,'Test Cases'!F2:F160,"Not Run") | H5: =IFERROR(C5/(C5+D5),0)
A6: neom_biofeedback | B6: =COUNTIF('Test Cases'!B2:B160,A6) | C6: =COUNTIFS('Test Cases'!B2:B160,A6,'Test Cases'!F2:F160,"Passed") | D6: =COUNTIFS('Test Cases'!B2:B160,A6,'Test Cases'!F2:F160,"Failed") | E6: =COUNTIFS('Test Cases'!B2:B160,A6,'Test Cases'!F2:F160,"Blocked") | F6: =COUNTIFS('Test Cases'!B2:B160,A6,'Test Cases'!F2:F160,"Skipped") | G6: =COUNTIFS('Test Cases'!B2:B160,A6,'Test Cases'!F2:F160,"Not Run") | H6: =IFERROR(C6/(C6+D6),0)
A7: neom_booking | B7: =COUNTIF('Test Cases'!B2:B160,A7) | C7: =COUNTIFS('Test Cases'!B2:B160,A7,'Test Cases'!F2:F160,"Passed") | D7: =COUNTIFS('Test Cases'!B2:B160,A7,'Test Cases'!F2:F160,"Failed") | E7: =COUNTIFS('Test Cases'!B2:B160,A7,'Test Cases'!F2:F160,"Blocked") | F7: =COUNTIFS('Test Cases'!B2:B160,A7,'Test Cases'!F2:F160,"Skipped") | G7: =COUNTIFS('Test Cases'!B2:B160,A7,'Test Cases'!F2:F160,"Not Run") | H7: =IFERROR(C7/(C7+D7),0)
A8: neom_books | B8: =COUNTIF('Test Cases'!B2:B160,A8) | C8: =COUNTIFS('Test Cases'!B2:B160,A8,'Test Cases'!F2:F160,"Passed") | D8: =COUNTIFS('Test Cases'!B2:B160,A8,'Test Cases'!F2:F160,"Failed") | E8: =COUNTIFS('Test Cases'!B2:B160,A8,'Test Cases'!F2:F160,"Blocked") | F8: =COUNTIFS('Test Cases'!B2:B160,A8,'Test Cases'!F2:F160,"Skipped") | G8: =COUNTIFS('Test Cases'!B2:B160,A8,'Test Cases'!F2:F160,"Not Run") | H8: =IFERROR(C8/(C8+D8),0)
A9: neom_calendar | B9: =COUNTIF('Test Cases'!B2:B160,A9) | C9: =COUNTIFS('Test Cases'!B2:B160,A9,'Test Cases'!F2:F160,"Passed") | D9: =COUNTIFS('Test Cases'!B2:B160,A9,'Test Cases'!F2:F160,"Failed") | E9: =COUNTIFS('Test Cases'!B2:B160,A9,'Test Cases'!F2:F160,"Blocked") | F9: =COUNTIFS('Test Cases'!B2:B160,A9,'Test Cases'!F2:F160,"Skipped") | G9: =COUNTIFS('Test Cases'!B2:B160,A9,'Test Cases'!F2:F160,"Not Run") | H9: =IFERROR(C9/(C9+D9),0)
A10: neom_camera | B10: =COUNTIF('Test Cases'!B2:B160,A10) | C10: =COUNTIFS('Test Cases'!B2:B160,A10,'Test Cases'!F2:F160,"Passed") | D10: =COUNTIFS('Test Cases'!B2:B160,A10,'Test Cases'!F2:F160,"Failed") | E10: =COUNTIFS('Test Cases'!B2:B160,A10,'Test Cases'!F2:F160,"Blocked") | F10: =COUNTIFS('Test Cases'!B2:B160,A10,'Test Cases'!F2:F160,"Skipped") | G10: =COUNTIFS('Test Cases'!B2:B160,A10,'Test Cases'!F2:F160,"Not Run") | H10: =IFERROR(C10/(C10+D10),0)
A11: neom_cloud | B11: =COUNTIF('Test Cases'!B2:B160,A11) | C11: =COUNTIFS('Test Cases'!B2:B160,A11,'Test Cases'!F2:F160,"Passed") | D11: =COUNTIFS('Test Cases'!B2:B160,A11,'Test Cases'!F2:F160,"Failed") | E11: =COUNTIFS('Test Cases'!B2:B160,A11,'Test Cases'!F2:F160,"Blocked") | F11: =COUNTIFS('Test Cases'!B2:B160,A11,'Test Cases'!F2:F160,"Skipped") | G11: =COUNTIFS('Test Cases'!B2:B160,A11,'Test Cases'!F2:F160,"Not Run") | H11: =IFERROR(C11/(C11+D11),0)
A12: neom_commons | B12: =COUNTIF('Test Cases'!B2:B160,A12) | C12: =COUNTIFS('Test Cases'!B2:B160,A12,'Test Cases'!F2:F160,"Passed") | D12: =COUNTIFS('Test Cases'!B2:B160,A12,'Test Cases'!F2:F160,"Failed") | E12: =COUNTIFS('Test Cases'!B2:B160,A12,'Test Cases'!F2:F160,"Blocked") | F12: =COUNTIFS('Test Cases'!B2:B160,A12,'Test Cases'!F2:F160,"Skipped") | G12: =COUNTIFS('Test Cases'!B2:B160,A12,'Test Cases'!F2:F160,"Not Run") | H12: =IFERROR(C12/(C12+D12),0)
A13: neom_downloads | B13: =COUNTIF('Test Cases'!B2:B160,A13) | C13: =COUNTIFS('Test Cases'!B2:B160,A13,'Test Cases'!F2:F160,"Passed") | D13: =COUNTIFS('Test Cases'!B2:B160,A13,'Test Cases'!F2:F160,"Failed") | E13: =COUNTIFS('Test Cases'!B2:B160,A13,'Test Cases'!F2:F160,"Blocked") | F13: =COUNTIFS('Test Cases'!B2:B160,A13,'Test Cases'!F2:F160,"Skipped") | G13: =COUNTIFS('Test Cases'!B2:B160,A13,'Test Cases'!F2:F160,"Not Run") | H13: =IFERROR(C13/(C13+D13),0)
A14: neom_erp | B14: =COUNTIF('Test Cases'!B2:B160,A14) | C14: =COUNTIFS('Test Cases'!B2:B160,A14,'Test Cases'!F2:F160,"Passed") | D14: =COUNTIFS('Test Cases'!B2:B160,A14,'Test Cases'!F2:F160,"Failed") | E14: =COUNTIFS('Test Cases'!B2:B160,A14,'Test Cases'!F2:F160,"Blocked") | F14: =COUNTIFS('Test Cases'!B2:B160,A14,'Test Cases'!F2:F160,"Skipped") | G14: =COUNTIFS('Test Cases'!B2:B160,A14,'Test Cases'!F2:F160,"Not Run") | H14: =IFERROR(C14/(C14+D14),0)
A15: neom_events | B15: =COUNTIF('Test Cases'!B2:B160,A15) | C15: =COUNTIFS('Test Cases'!B2:B160,A15,'Test Cases'!F2:F160,"Passed") | D15: =COUNTIFS('Test Cases'!B2:B160,A15,'Test Cases'!F2:F160,"Failed") | E15: =COUNTIFS('Test Cases'!B2:B160,A15,'Test Cases'!F2:F160,"Blocked") | F15: =COUNTIFS('Test Cases'!B2:B160,A15,'Test Cases'!F2:F160,"Skipped") | G15: =COUNTIFS('Test Cases'!B2:B160,A15,'Test Cases'!F2:F160,"Not Run") | H15: =IFERROR(C15/(C15+D15),0)
A16: neom_experiences | B16: =COUNTIF('Test Cases'!B2:B160,A16) | C16: =COUNTIFS('Test Cases'!B2:B160,A16,'Test Cases'!F2:F160,"Passed") | D16: =COUNTIFS('Test Cases'!B2:B160,A16,'Test Cases'!F2:F160,"Failed") | E16: =COUNTIFS('Test Cases'!B2:B160,A16,'Test Cases'!F2:F160,"Blocked") | F16: =COUNTIFS('Test Cases'!B2:B160,A16,'Test Cases'!F2:F160,"Skipped") | G16: =COUNTIFS('Test Cases'!B2:B160,A16,'Test Cases'!F2:F160,"Not Run") | H16: =IFERROR(C16/(C16+D16),0)
A17: neom_frequencies | B17: =COUNTIF('Test Cases'!B2:B160,A17) | C17: =COUNTIFS('Test Cases'!B2:B160,A17,'Test Cases'!F2:F160,"Passed") | D17: =COUNTIFS('Test Cases'!B2:B160,A17,'Test Cases'!F2:F160,"Failed") | E17: =COUNTIFS('Test Cases'!B2:B160,A17,'Test Cases'!F2:F160,"Blocked") | F17: =COUNTIFS('Test Cases'!B2:B160,A17,'Test Cases'!F2:F160,"Skipped") | G17: =COUNTIFS('Test Cases'!B2:B160,A17,'Test Cases'!F2:F160,"Not Run") | H17: =IFERROR(C17/(C17+D17),0)
A18: neom_generator | B18: =COUNTIF('Test Cases'!B2:B160,A18) | C18: =COUNTIFS('Test Cases'!B2:B160,A18,'Test Cases'!F2:F160,"Passed") | D18: =COUNTIFS('Test Cases'!B2:B160,A18,'Test Cases'!F2:F160,"Failed") | E18: =COUNTIFS('Test Cases'!B2:B160,A18,'Test Cases'!F2:F160,"Blocked") | F18: =COUNTIFS('Test Cases'!B2:B160,A18,'Test Cases'!F2:F160,"Skipped") | G18: =COUNTIFS('Test Cases'!B2:B160,A18,'Test Cases'!F2:F160,"Not Run") | H18: =IFERROR(C18/(C18+D18),0)
A19: neom_historic_state | B19: =COUNTIF('Test Cases'!B2:B160,A19) | C19: =COUNTIFS('Test Cases'!B2:B160,A19,'Test Cases'!F2:F160,"Passed") | D19: =COUNTIFS('Test Cases'!B2:B160,A19,'Test Cases'!F2:F160,"Failed") | E19: =COUNTIFS('Test Cases'!B2:B160,A19,'Test Cases'!F2:F160,"Blocked") | F19: =COUNTIFS('Test Cases'!B2:B160,A19,'Test Cases'!F2:F160,"Skipped") | G19: =COUNTIFS('Test Cases'!B2:B160,A19,'Test Cases'!F2:F160,"Not Run") | H19: =IFERROR(C19/(C19+D19),0)
A20: neom_home | B20: =COUNTIF('Test Cases'!B2:B160,A20) | C20: =COUNTIFS('Test Cases'!B2:B160,A20,'Test Cases'!F2:F160,"Passed") | D20: =COUNTIFS('Test Cases'!B2:B160,A20,'Test Cases'!F2:F160,"Failed") | E20: =COUNTIFS('Test Cases'!B2:B160,A20,'Test Cases'!F2:F160,"Blocked") | F20: =COUNTIFS('Test Cases'!B2:B160,A20,'Test Cases'!F2:F160,"Skipped") | G20: =COUNTIFS('Test Cases'!B2:B160,A20,'Test Cases'!F2:F160,"Not Run") | H20: =IFERROR(C20/(C20+D20),0)
A21: neom_ia | B21: =COUNTIF('Test Cases'!B2:B160,A21) | C21: =COUNTIFS('Test Cases'!B2:B160,A21,'Test Cases'!F2:F160,"Passed") | D21: =COUNTIFS('Test Cases'!B2:B160,A21,'Test Cases'!F2:F160,"Failed") | E21: =COUNTIFS('Test Cases'!B2:B160,A21,'Test Cases'!F2:F160,"Blocked") | F21: =COUNTIFS('Test Cases'!B2:B160,A21,'Test Cases'!F2:F160,"Skipped") | G21: =COUNTIFS('Test Cases'!B2:B160,A21,'Test Cases'!F2:F160,"Not Run") | H21: =IFERROR(C21/(C21+D21),0)
A22: neom_image_editor | B22: =COUNTIF('Test Cases'!B2:B160,A22) | C22: =COUNTIFS('Test Cases'!B2:B160,A22,'Test Cases'!F2:F160,"Passed") | D22: =COUNTIFS('Test Cases'!B2:B160,A22,'Test Cases'!F2:F160,"Failed") | E22: =COUNTIFS('Test Cases'!B2:B160,A22,'Test Cases'!F2:F160,"Blocked") | F22: =COUNTIFS('Test Cases'!B2:B160,A22,'Test Cases'!F2:F160,"Skipped") | G22: =COUNTIFS('Test Cases'!B2:B160,A22,'Test Cases'!F2:F160,"Not Run") | H22: =IFERROR(C22/(C22+D22),0)
A23: neom_inbox | B23: =COUNTIF('Test Cases'!B2:B160,A23) | C23: =COUNTIFS('Test Cases'!B2:B160,A23,'Test Cases'!F2:F160,"Passed") | D23: =COUNTIFS('Test Cases'!B2:B160,A23,'Test Cases'!F2:F160,"Failed") | E23: =COUNTIFS('Test Cases'!B2:B160,A23,'Test Cases'!F2:F160,"Blocked") | F23: =COUNTIFS('Test Cases'!B2:B160,A23,'Test Cases'!F2:F160,"Skipped") | G23: =COUNTIFS('Test Cases'!B2:B160,A23,'Test Cases'!F2:F160,"Not Run") | H23: =IFERROR(C23/(C23+D23),0)
A24: neom_inter | B24: =COUNTIF('Test Cases'!B2:B160,A24) | C24: =COUNTIFS('Test Cases'!B2:B160,A24,'Test Cases'!F2:F160,"Passed") | D24: =COUNTIFS('Test Cases'!B2:B160,A24,'Test Cases'!F2:F160,"Failed") | E24: =COUNTIFS('Test Cases'!B2:B160,A24,'Test Cases'!F2:F160,"Blocked") | F24: =COUNTIFS('Test Cases'!B2:B160,A24,'Test Cases'!F2:F160,"Skipped") | G24: =COUNTIFS('Test Cases'!B2:B160,A24,'Test Cases'!F2:F160,"Not Run") | H24: =IFERROR(C24/(C24+D24),0)
A25: neom_learning | B25: =COUNTIF('Test Cases'!B2:B160,A25) | C25: =COUNTIFS('Test Cases'!B2:B160,A25,'Test Cases'!F2:F160,"Passed") | D25: =COUNTIFS('Test Cases'!B2:B160,A25,'Test Cases'!F2:F160,"Failed") | E25: =COUNTIFS('Test Cases'!B2:B160,A25,'Test Cases'!F2:F160,"Blocked") | F25: =COUNTIFS('Test Cases'!B2:B160,A25,'Test Cases'!F2:F160,"Skipped") | G25: =COUNTIFS('Test Cases'!B2:B160,A25,'Test Cases'!F2:F160,"Not Run") | H25: =IFERROR(C25/(C25+D25),0)
A26: neom_mates | B26: =COUNTIF('Test Cases'!B2:B160,A26) | C26: =COUNTIFS('Test Cases'!B2:B160,A26,'Test Cases'!F2:F160,"Passed") | D26: =COUNTIFS('Test Cases'!B2:B160,A26,'Test Cases'!F2:F160,"Failed") | E26: =COUNTIFS('Test Cases'!B2:B160,A26,'Test Cases'!F2:F160,"Blocked") | F26: =COUNTIFS('Test Cases'!B2:B160,A26,'Test Cases'!F2:F160,"Skipped") | G26: =COUNTIFS('Test Cases'!B2:B160,A26,'Test Cases'!F2:F160,"Not Run") | H26: =IFERROR(C26/(C26+D26),0)
A27: neom_media_upload | B27: =COUNTIF('Test Cases'!B2:B160,A27) | C27: =COUNTIFS('Test Cases'!B2:B160,A27,'Test Cases'!F2:F160,"Passed") | D27: =COUNTIFS('Test Cases'!B2:B160,A27,'Test Cases'!F2:F160,"Failed") | E27: =COUNTIFS('Test Cases'!B2:B160,A27,'Test Cases'!F2:F160,"Blocked") | F27: =COUNTIFS('Test Cases'!B2:B160,A27,'Test Cases'!F2:F160,"Skipped") | G27: =COUNTIFS('Test Cases'!B2:B160,A27,'Test Cases'!F2:F160,"Not Run") | H27: =IFERROR(C27/(C27+D27),0)
A28: neom_notifications | B28: =COUNTIF('Test Cases'!B2:B160,A28) | C28: =COUNTIFS('Test Cases'!B2:B160,A28,'Test Cases'!F2:F160,"Passed") | D28: =COUNTIFS('Test Cases'!B2:B160,A28,'Test Cases'!F2:F160,"Failed") | E28: =COUNTIFS('Test Cases'!B2:B160,A28,'Test Cases'!F2:F160,"Blocked") | F28: =COUNTIFS('Test Cases'!B2:B160,A28,'Test Cases'!F2:F160,"Skipped") | G28: =COUNTIFS('Test Cases'!B2:B160,A28,'Test Cases'!F2:F160,"Not Run") | H28: =IFERROR(C28/(C28+D28),0)
A29: neom_onboarding | B29: =COUNTIF('Test Cases'!B2:B160,A29) | C29: =COUNTIFS('Test Cases'!B2:B160,A29,'Test Cases'!F2:F160,"Passed") | D29: =COUNTIFS('Test Cases'!B2:B160,A29,'Test Cases'!F2:F160,"Failed") | E29: =COUNTIFS('Test Cases'!B2:B160,A29,'Test Cases'!F2:F160,"Blocked") | F29: =COUNTIFS('Test Cases'!B2:B160,A29,'Test Cases'!F2:F160,"Skipped") | G29: =COUNTIFS('Test Cases'!B2:B160,A29,'Test Cases'!F2:F160,"Not Run") | H29: =IFERROR(C29/(C29+D29),0)
A30: neom_par | B30: =COUNTIF('Test Cases'!B2:B160,A30) | C30: =COUNTIFS('Test Cases'!B2:B160,A30,'Test Cases'!F2:F160,"Passed") | D30: =COUNTIFS('Test Cases'!B2:B160,A30,'Test Cases'!F2:F160,"Failed") | E30: =COUNTIFS('Test Cases'!B2:B160,A30,'Test Cases'!F2:F160,"Blocked") | F30: =COUNTIFS('Test Cases'!B2:B160,A30,'Test Cases'!F2:F160,"Skipped") | G30: =COUNTIFS('Test Cases'!B2:B160,A30,'Test Cases'!F2:F160,"Not Run") | H30: =IFERROR(C30/(C30+D30),0)
A31: neom_posts | B31: =COUNTIF('Test Cases'!B2:B160,A31) | C31: =COUNTIFS('Test Cases'!B2:B160,A31,'Test Cases'!F2:F160,"Passed") | D31: =COUNTIFS('Test Cases'!B2:B160,A31,'Test Cases'!F2:F160,"Failed") | E31: =COUNTIFS('Test Cases'!B2:B160,A31,'Test Cases'!F2:F160,"Blocked") | F31: =COUNTIFS('Test Cases'!B2:B160,A31,'Test Cases'!F2:F160,"Skipped") | G31: =COUNTIFS('Test Cases'!B2:B160,A31,'Test Cases'!F2:F160,"Not Run") | H31: =IFERROR(C31/(C31+D31),0)
A32: neom_profile | B32: =COUNTIF('Test Cases'!B2:B160,A32) | C32: =COUNTIFS('Test Cases'!B2:B160,A32,'Test Cases'!F2:F160,"Passed") | D32: =COUNTIFS('Test Cases'!B2:B160,A32,'Test Cases'!F2:F160,"Failed") | E32: =COUNTIFS('Test Cases'!B2:B160,A32,'Test Cases'!F2:F160,"Blocked") | F32: =COUNTIFS('Test Cases'!B2:B160,A32,'Test Cases'!F2:F160,"Skipped") | G32: =COUNTIFS('Test Cases'!B2:B160,A32,'Test Cases'!F2:F160,"Not Run") | H32: =IFERROR(C32/(C32+D32),0)
A33: neom_releases | B33: =COUNTIF('Test Cases'!B2:B160,A33) | C33: =COUNTIFS('Test Cases'!B2:B160,A33,'Test Cases'!F2:F160,"Passed") | D33: =COUNTIFS('Test Cases'!B2:B160,A33,'Test Cases'!F2:F160,"Failed") | E33: =COUNTIFS('Test Cases'!B2:B160,A33,'Test Cases'!F2:F160,"Blocked") | F33: =COUNTIFS('Test Cases'!B2:B160,A33,'Test Cases'!F2:F160,"Skipped") | G33: =COUNTIFS('Test Cases'!B2:B160,A33,'Test Cases'!F2:F160,"Not Run") | H33: =IFERROR(C33/(C33+D33),0)
A34: neom_search | B34: =COUNTIF('Test Cases'!B2:B160,A34) | C34: =COUNTIFS('Test Cases'!B2:B160,A34,'Test Cases'!F2:F160,"Passed") | D34: =COUNTIFS('Test Cases'!B2:B160,A34,'Test Cases'!F2:F160,"Failed") | E34: =COUNTIFS('Test Cases'!B2:B160,A34,'Test Cases'!F2:F160,"Blocked") | F34: =COUNTIFS('Test Cases'!B2:B160,A34,'Test Cases'!F2:F160,"Skipped") | G34: =COUNTIFS('Test Cases'!B2:B160,A34,'Test Cases'!F2:F160,"Not Run") | H34: =IFERROR(C34/(C34+D34),0)
A35: neom_settings | B35: =COUNTIF('Test Cases'!B2:B160,A35) | C35: =COUNTIFS('Test Cases'!B2:B160,A35,'Test Cases'!F2:F160,"Passed") | D35: =COUNTIFS('Test Cases'!B2:B160,A35,'Test Cases'!F2:F160,"Failed") | E35: =COUNTIFS('Test Cases'!B2:B160,A35,'Test Cases'!F2:F160,"Blocked") | F35: =COUNTIFS('Test Cases'!B2:B160,A35,'Test Cases'!F2:F160,"Skipped") | G35: =COUNTIFS('Test Cases'!B2:B160,A35,'Test Cases'!F2:F160,"Not Run") | H35: =IFERROR(C35/(C35+D35),0)
A36: neom_states | B36: =COUNTIF('Test Cases'!B2:B160,A36) | C36: =COUNTIFS('Test Cases'!B2:B160,A36,'Test Cases'!F2:F160,"Passed") | D36: =COUNTIFS('Test Cases'!B2:B160,A36,'Test Cases'!F2:F160,"Failed") | E36: =COUNTIFS('Test Cases'!B2:B160,A36,'Test Cases'!F2:F160,"Blocked") | F36: =COUNTIFS('Test Cases'!B2:B160,A36,'Test Cases'!F2:F160,"Skipped") | G36: =COUNTIFS('Test Cases'!B2:B160,A36,'Test Cases'!F2:F160,"Not Run") | H36: =IFERROR(C36/(C36+D36),0)
A37: neom_stripe | B37: =COUNTIF('Test Cases'!B2:B160,A37) | C37: =COUNTIFS('Test Cases'!B2:B160,A37,'Test Cases'!F2:F160,"Passed") | D37: =COUNTIFS('Test Cases'!B2:B160,A37,'Test Cases'!F2:F160,"Failed") | E37: =COUNTIFS('Test Cases'!B2:B160,A37,'Test Cases'!F2:F160,"Blocked") | F37: =COUNTIFS('Test Cases'!B2:B160,A37,'Test Cases'!F2:F160,"Skipped") | G37: =COUNTIFS('Test Cases'!B2:B160,A37,'Test Cases'!F2:F160,"Not Run") | H37: =IFERROR(C37/(C37+D37),0)
A38: neom_tts | B38: =COUNTIF('Test Cases'!B2:B160,A38) | C38: =COUNTIFS('Test Cases'!B2:B160,A38,'Test Cases'!F2:F160,"Passed") | D38: =COUNTIFS('Test Cases'!B2:B160,A38,'Test Cases'!F2:F160,"Failed") | E38: =COUNTIFS('Test Cases'!B2:B160,A38,'Test Cases'!F2:F160,"Blocked") | F38: =COUNTIFS('Test Cases'!B2:B160,A38,'Test Cases'!F2:F160,"Skipped") | G38: =COUNTIFS('Test Cases'!B2:B160,A38,'Test Cases'!F2:F160,"Not Run") | H38: =IFERROR(C38/(C38+D38),0)
A39: neom_vr | B39: =COUNTIF('Test Cases'!B2:B160,A39) | C39: =COUNTIFS('Test Cases'!B2:B160,A39,'Test Cases'!F2:F160,"Passed") | D39: =COUNTIFS('Test Cases'!B2:B160,A39,'Test Cases'!F2:F160,"Failed") | E39: =COUNTIFS('Test Cases'!B2:B160,A39,'Test Cases'!F2:F160,"Blocked") | F39: =COUNTIFS('Test Cases'!B2:B160,A39,'Test Cases'!F2:F160,"Skipped") | G39: =COUNTIFS('Test Cases'!B2:B160,A39,'Test Cases'!F2:F160,"Not Run") | H39: =IFERROR(C39/(C39+D39),0)

Sheet By Area
A1: Area | B1: Total | C1: Passed | D1: Failed | E1: Pendientes | F1: % Pass
A2: A11y | B2: =COUNTIF('Test Cases'!C2:C160,A2) | C2: =COUNTIFS('Test Cases'!C2:C160,A2,'Test Cases'!F2:F160,"Passed") | D2: =COUNTIFS('Test Cases'!C2:C160,A2,'Test Cases'!F2:F160,"Failed") | E2: =COUNTIFS('Test Cases'!C2:C160,A2,'Test Cases'!F2:F160,"Not Run") | F2: =IFERROR(C2/(C2+D2),0)
A3: Admin | B3: =COUNTIF('Test Cases'!C2:C160,A3) | C3: =COUNTIFS('Test Cases'!C2:C160,A3,'Test Cases'!F2:F160,"Passed") | D3: =COUNTIFS('Test Cases'!C2:C160,A3,'Test Cases'!F2:F160,"Failed") | E3: =COUNTIFS('Test Cases'!C2:C160,A3,'Test Cases'!F2:F160,"Not Run") | F3: =IFERROR(C3/(C3+D3),0)
A4: Audio | B4: =COUNTIF('Test Cases'!C2:C160,A4) | C4: =COUNTIFS('Test Cases'!C2:C160,A4,'Test Cases'!F2:F160,"Passed") | D4: =COUNTIFS('Test Cases'!C2:C160,A4,'Test Cases'!F2:F160,"Failed") | E4: =COUNTIFS('Test Cases'!C2:C160,A4,'Test Cases'!F2:F160,"Not Run") | F4: =IFERROR(C4/(C4+D4),0)
A5: Auth | B5: =COUNTIF('Test Cases'!C2:C160,A5) | C5: =COUNTIFS('Test Cases'!C2:C160,A5,'Test Cases'!F2:F160,"Passed") | D5: =COUNTIFS('Test Cases'!C2:C160,A5,'Test Cases'!F2:F160,"Failed") | E5: =COUNTIFS('Test Cases'!C2:C160,A5,'Test Cases'!F2:F160,"Not Run") | F5: =IFERROR(C5/(C5+D5),0)
A6: Biofeedback | B6: =COUNTIF('Test Cases'!C2:C160,A6) | C6: =COUNTIFS('Test Cases'!C2:C160,A6,'Test Cases'!F2:F160,"Passed") | D6: =COUNTIFS('Test Cases'!C2:C160,A6,'Test Cases'!F2:F160,"Failed") | E6: =COUNTIFS('Test Cases'!C2:C160,A6,'Test Cases'!F2:F160,"Not Run") | F6: =IFERROR(C6/(C6+D6),0)
A7: Booking | B7: =COUNTIF('Test Cases'!C2:C160,A7) | C7: =COUNTIFS('Test Cases'!C2:C160,A7,'Test Cases'!F2:F160,"Passed") | D7: =COUNTIFS('Test Cases'!C2:C160,A7,'Test Cases'!F2:F160,"Failed") | E7: =COUNTIFS('Test Cases'!C2:C160,A7,'Test Cases'!F2:F160,"Not Run") | F7: =IFERROR(C7/(C7+D7),0)
A8: Books | B8: =COUNTIF('Test Cases'!C2:C160,A8) | C8: =COUNTIFS('Test Cases'!C2:C160,A8,'Test Cases'!F2:F160,"Passed") | D8: =COUNTIFS('Test Cases'!C2:C160,A8,'Test Cases'!F2:F160,"Failed") | E8: =COUNTIFS('Test Cases'!C2:C160,A8,'Test Cases'!F2:F160,"Not Run") | F8: =IFERROR(C8/(C8+D8),0)
A9: Calendar | B9: =COUNTIF('Test Cases'!C2:C160,A9) | C9: =COUNTIFS('Test Cases'!C2:C160,A9,'Test Cases'!F2:F160,"Passed") | D9: =COUNTIFS('Test Cases'!C2:C160,A9,'Test Cases'!F2:F160,"Failed") | E9: =COUNTIFS('Test Cases'!C2:C160,A9,'Test Cases'!F2:F160,"Not Run") | F9: =IFERROR(C9/(C9+D9),0)
A10: Camera | B10: =COUNTIF('Test Cases'!C2:C160,A10) | C10: =COUNTIFS('Test Cases'!C2:C160,A10,'Test Cases'!F2:F160,"Passed") | D10: =COUNTIFS('Test Cases'!C2:C160,A10,'Test Cases'!F2:F160,"Failed") | E10: =COUNTIFS('Test Cases'!C2:C160,A10,'Test Cases'!F2:F160,"Not Run") | F10: =IFERROR(C10/(C10+D10),0)
A11: Cloud | B11: =COUNTIF('Test Cases'!C2:C160,A11) | C11: =COUNTIFS('Test Cases'!C2:C160,A11,'Test Cases'!F2:F160,"Passed") | D11: =COUNTIFS('Test Cases'!C2:C160,A11,'Test Cases'!F2:F160,"Failed") | E11: =COUNTIFS('Test Cases'!C2:C160,A11,'Test Cases'!F2:F160,"Not Run") | F11: =IFERROR(C11/(C11+D11),0)
A12: Cross | B12: =COUNTIF('Test Cases'!C2:C160,A12) | C12: =COUNTIFS('Test Cases'!C2:C160,A12,'Test Cases'!F2:F160,"Passed") | D12: =COUNTIFS('Test Cases'!C2:C160,A12,'Test Cases'!F2:F160,"Failed") | E12: =COUNTIFS('Test Cases'!C2:C160,A12,'Test Cases'!F2:F160,"Not Run") | F12: =IFERROR(C12/(C12+D12),0)
A13: Downloads | B13: =COUNTIF('Test Cases'!C2:C160,A13) | C13: =COUNTIFS('Test Cases'!C2:C160,A13,'Test Cases'!F2:F160,"Passed") | D13: =COUNTIFS('Test Cases'!C2:C160,A13,'Test Cases'!F2:F160,"Failed") | E13: =COUNTIFS('Test Cases'!C2:C160,A13,'Test Cases'!F2:F160,"Not Run") | F13: =IFERROR(C13/(C13+D13),0)
A14: ERP | B14: =COUNTIF('Test Cases'!C2:C160,A14) | C14: =COUNTIFS('Test Cases'!C2:C160,A14,'Test Cases'!F2:F160,"Passed") | D14: =COUNTIFS('Test Cases'!C2:C160,A14,'Test Cases'!F2:F160,"Failed") | E14: =COUNTIFS('Test Cases'!C2:C160,A14,'Test Cases'!F2:F160,"Not Run") | F14: =IFERROR(C14/(C14+D14),0)
A15: Embed | B15: =COUNTIF('Test Cases'!C2:C160,A15) | C15: =COUNTIFS('Test Cases'!C2:C160,A15,'Test Cases'!F2:F160,"Passed") | D15: =COUNTIFS('Test Cases'!C2:C160,A15,'Test Cases'!F2:F160,"Failed") | E15: =COUNTIFS('Test Cases'!C2:C160,A15,'Test Cases'!F2:F160,"Not Run") | F15: =IFERROR(C15/(C15+D15),0)
A16: Errors | B16: =COUNTIF('Test Cases'!C2:C160,A16) | C16: =COUNTIFS('Test Cases'!C2:C160,A16,'Test Cases'!F2:F160,"Passed") | D16: =COUNTIFS('Test Cases'!C2:C160,A16,'Test Cases'!F2:F160,"Failed") | E16: =COUNTIFS('Test Cases'!C2:C160,A16,'Test Cases'!F2:F160,"Not Run") | F16: =IFERROR(C16/(C16+D16),0)
A17: Events | B17: =COUNTIF('Test Cases'!C2:C160,A17) | C17: =COUNTIFS('Test Cases'!C2:C160,A17,'Test Cases'!F2:F160,"Passed") | D17: =COUNTIFS('Test Cases'!C2:C160,A17,'Test Cases'!F2:F160,"Failed") | E17: =COUNTIFS('Test Cases'!C2:C160,A17,'Test Cases'!F2:F160,"Not Run") | F17: =IFERROR(C17/(C17+D17),0)
A18: Experiences | B18: =COUNTIF('Test Cases'!C2:C160,A18) | C18: =COUNTIFS('Test Cases'!C2:C160,A18,'Test Cases'!F2:F160,"Passed") | D18: =COUNTIFS('Test Cases'!C2:C160,A18,'Test Cases'!F2:F160,"Failed") | E18: =COUNTIFS('Test Cases'!C2:C160,A18,'Test Cases'!F2:F160,"Not Run") | F18: =IFERROR(C18/(C18+D18),0)
A19: Frequencies | B19: =COUNTIF('Test Cases'!C2:C160,A19) | C19: =COUNTIFS('Test Cases'!C2:C160,A19,'Test Cases'!F2:F160,"Passed") | D19: =COUNTIFS('Test Cases'!C2:C160,A19,'Test Cases'!F2:F160,"Failed") | E19: =COUNTIFS('Test Cases'!C2:C160,A19,'Test Cases'!F2:F160,"Not Run") | F19: =IFERROR(C19/(C19+D19),0)
A20: Generator | B20: =COUNTIF('Test Cases'!C2:C160,A20) | C20: =COUNTIFS('Test Cases'!C2:C160,A20,'Test Cases'!F2:F160,"Passed") | D20: =COUNTIFS('Test Cases'!C2:C160,A20,'Test Cases'!F2:F160,"Failed") | E20: =COUNTIFS('Test Cases'!C2:C160,A20,'Test Cases'!F2:F160,"Not Run") | F20: =IFERROR(C20/(C20+D20),0)
A21: HistoricState | B21: =COUNTIF('Test Cases'!C2:C160,A21) | C21: =COUNTIFS('Test Cases'!C2:C160,A21,'Test Cases'!F2:F160,"Passed") | D21: =COUNTIFS('Test Cases'!C2:C160,A21,'Test Cases'!F2:F160,"Failed") | E21: =COUNTIFS('Test Cases'!C2:C160,A21,'Test Cases'!F2:F160,"Not Run") | F21: =IFERROR(C21/(C21+D21),0)
A22: Home | B22: =COUNTIF('Test Cases'!C2:C160,A22) | C22: =COUNTIFS('Test Cases'!C2:C160,A22,'Test Cases'!F2:F160,"Passed") | D22: =COUNTIFS('Test Cases'!C2:C160,A22,'Test Cases'!F2:F160,"Failed") | E22: =COUNTIFS('Test Cases'!C2:C160,A22,'Test Cases'!F2:F160,"Not Run") | F22: =IFERROR(C22/(C22+D22),0)
A23: ImgEdit | B23: =COUNTIF('Test Cases'!C2:C160,A23) | C23: =COUNTIFS('Test Cases'!C2:C160,A23,'Test Cases'!F2:F160,"Passed") | D23: =COUNTIFS('Test Cases'!C2:C160,A23,'Test Cases'!F2:F160,"Failed") | E23: =COUNTIFS('Test Cases'!C2:C160,A23,'Test Cases'!F2:F160,"Not Run") | F23: =IFERROR(C23/(C23+D23),0)
A24: Inbox | B24: =COUNTIF('Test Cases'!C2:C160,A24) | C24: =COUNTIFS('Test Cases'!C2:C160,A24,'Test Cases'!F2:F160,"Passed") | D24: =COUNTIFS('Test Cases'!C2:C160,A24,'Test Cases'!F2:F160,"Failed") | E24: =COUNTIFS('Test Cases'!C2:C160,A24,'Test Cases'!F2:F160,"Not Run") | F24: =IFERROR(C24/(C24+D24),0)
A25: Inter | B25: =COUNTIF('Test Cases'!C2:C160,A25) | C25: =COUNTIFS('Test Cases'!C2:C160,A25,'Test Cases'!F2:F160,"Passed") | D25: =COUNTIFS('Test Cases'!C2:C160,A25,'Test Cases'!F2:F160,"Failed") | E25: =COUNTIFS('Test Cases'!C2:C160,A25,'Test Cases'!F2:F160,"Not Run") | F25: =IFERROR(C25/(C25+D25),0)
A26: Learning | B26: =COUNTIF('Test Cases'!C2:C160,A26) | C26: =COUNTIFS('Test Cases'!C2:C160,A26,'Test Cases'!F2:F160,"Passed") | D26: =COUNTIFS('Test Cases'!C2:C160,A26,'Test Cases'!F2:F160,"Failed") | E26: =COUNTIFS('Test Cases'!C2:C160,A26,'Test Cases'!F2:F160,"Not Run") | F26: =IFERROR(C26/(C26+D26),0)
A27: Mates | B27: =COUNTIF('Test Cases'!C2:C160,A27) | C27: =COUNTIFS('Test Cases'!C2:C160,A27,'Test Cases'!F2:F160,"Passed") | D27: =COUNTIFS('Test Cases'!C2:C160,A27,'Test Cases'!F2:F160,"Failed") | E27: =COUNTIFS('Test Cases'!C2:C160,A27,'Test Cases'!F2:F160,"Not Run") | F27: =IFERROR(C27/(C27+D27),0)
A28: Notif | B28: =COUNTIF('Test Cases'!C2:C160,A28) | C28: =COUNTIFS('Test Cases'!C2:C160,A28,'Test Cases'!F2:F160,"Passed") | D28: =COUNTIFS('Test Cases'!C2:C160,A28,'Test Cases'!F2:F160,"Failed") | E28: =COUNTIFS('Test Cases'!C2:C160,A28,'Test Cases'!F2:F160,"Not Run") | F28: =IFERROR(C28/(C28+D28),0)
A29: Onboarding | B29: =COUNTIF('Test Cases'!C2:C160,A29) | C29: =COUNTIFS('Test Cases'!C2:C160,A29,'Test Cases'!F2:F160,"Passed") | D29: =COUNTIFS('Test Cases'!C2:C160,A29,'Test Cases'!F2:F160,"Failed") | E29: =COUNTIFS('Test Cases'!C2:C160,A29,'Test Cases'!F2:F160,"Not Run") | F29: =IFERROR(C29/(C29+D29),0)
A30: PAR | B30: =COUNTIF('Test Cases'!C2:C160,A30) | C30: =COUNTIFS('Test Cases'!C2:C160,A30,'Test Cases'!F2:F160,"Passed") | D30: =COUNTIFS('Test Cases'!C2:C160,A30,'Test Cases'!F2:F160,"Failed") | E30: =COUNTIFS('Test Cases'!C2:C160,A30,'Test Cases'!F2:F160,"Not Run") | F30: =IFERROR(C30/(C30+D30),0)
A31: Performance | B31: =COUNTIF('Test Cases'!C2:C160,A31) | C31: =COUNTIFS('Test Cases'!C2:C160,A31,'Test Cases'!F2:F160,"Passed") | D31: =COUNTIFS('Test Cases'!C2:C160,A31,'Test Cases'!F2:F160,"Failed") | E31: =COUNTIFS('Test Cases'!C2:C160,A31,'Test Cases'!F2:F160,"Not Run") | F31: =IFERROR(C31/(C31+D31),0)
A32: Posts | B32: =COUNTIF('Test Cases'!C2:C160,A32) | C32: =COUNTIFS('Test Cases'!C2:C160,A32,'Test Cases'!F2:F160,"Passed") | D32: =COUNTIFS('Test Cases'!C2:C160,A32,'Test Cases'!F2:F160,"Failed") | E32: =COUNTIFS('Test Cases'!C2:C160,A32,'Test Cases'!F2:F160,"Not Run") | F32: =IFERROR(C32/(C32+D32),0)
A33: Profile | B33: =COUNTIF('Test Cases'!C2:C160,A33) | C33: =COUNTIFS('Test Cases'!C2:C160,A33,'Test Cases'!F2:F160,"Passed") | D33: =COUNTIFS('Test Cases'!C2:C160,A33,'Test Cases'!F2:F160,"Failed") | E33: =COUNTIFS('Test Cases'!C2:C160,A33,'Test Cases'!F2:F160,"Not Run") | F33: =IFERROR(C33/(C33+D33),0)
A34: Releases | B34: =COUNTIF('Test Cases'!C2:C160,A34) | C34: =COUNTIFS('Test Cases'!C2:C160,A34,'Test Cases'!F2:F160,"Passed") | D34: =COUNTIFS('Test Cases'!C2:C160,A34,'Test Cases'!F2:F160,"Failed") | E34: =COUNTIFS('Test Cases'!C2:C160,A34,'Test Cases'!F2:F160,"Not Run") | F34: =IFERROR(C34/(C34+D34),0)
A35: Routing | B35: =COUNTIF('Test Cases'!C2:C160,A35) | C35: =COUNTIFS('Test Cases'!C2:C160,A35,'Test Cases'!F2:F160,"Passed") | D35: =COUNTIFS('Test Cases'!C2:C160,A35,'Test Cases'!F2:F160,"Failed") | E35: =COUNTIFS('Test Cases'!C2:C160,A35,'Test Cases'!F2:F160,"Not Run") | F35: =IFERROR(C35/(C35+D35),0)
A36: Search | B36: =COUNTIF('Test Cases'!C2:C160,A36) | C36: =COUNTIFS('Test Cases'!C2:C160,A36,'Test Cases'!F2:F160,"Passed") | D36: =COUNTIFS('Test Cases'!C2:C160,A36,'Test Cases'!F2:F160,"Failed") | E36: =COUNTIFS('Test Cases'!C2:C160,A36,'Test Cases'!F2:F160,"Not Run") | F36: =IFERROR(C36/(C36+D36),0)
A37: Security | B37: =COUNTIF('Test Cases'!C2:C160,A37) | C37: =COUNTIFS('Test Cases'!C2:C160,A37,'Test Cases'!F2:F160,"Passed") | D37: =COUNTIFS('Test Cases'!C2:C160,A37,'Test Cases'!F2:F160,"Failed") | E37: =COUNTIFS('Test Cases'!C2:C160,A37,'Test Cases'!F2:F160,"Not Run") | F37: =IFERROR(C37/(C37+D37),0)
A38: Settings | B38: =COUNTIF('Test Cases'!C2:C160,A38) | C38: =COUNTIFS('Test Cases'!C2:C160,A38,'Test Cases'!F2:F160,"Passed") | D38: =COUNTIFS('Test Cases'!C2:C160,A38,'Test Cases'!F2:F160,"Failed") | E38: =COUNTIFS('Test Cases'!C2:C160,A38,'Test Cases'!F2:F160,"Not Run") | F38: =IFERROR(C38/(C38+D38),0)
A39: Smoke | B39: =COUNTIF('Test Cases'!C2:C160,A39) | C39: =COUNTIFS('Test Cases'!C2:C160,A39,'Test Cases'!F2:F160,"Passed") | D39: =COUNTIFS('Test Cases'!C2:C160,A39,'Test Cases'!F2:F160,"Failed") | E39: =COUNTIFS('Test Cases'!C2:C160,A39,'Test Cases'!F2:F160,"Not Run") | F39: =IFERROR(C39/(C39+D39),0)
A40: States | B40: =COUNTIF('Test Cases'!C2:C160,A40) | C40: =COUNTIFS('Test Cases'!C2:C160,A40,'Test Cases'!F2:F160,"Passed") | D40: =COUNTIFS('Test Cases'!C2:C160,A40,'Test Cases'!F2:F160,"Failed") | E40: =COUNTIFS('Test Cases'!C2:C160,A40,'Test Cases'!F2:F160,"Not Run") | F40: =IFERROR(C40/(C40+D40),0)
...

Sheet Defects Log
A1: Defect ID | B1: Case Code | C1: Severity | D1: Title | E1: Steps | F1: Actual | G1: Expected | H1: Platform | I1: Screenshot URL | J1: Assigned | K1: Status | L1: Created | M1: Closed

Sheet Release Gates
A1: Criterios de aceptación (Release Gates)
A3: Criterio | B3: Target | C3: Estado
A4: P0 con 100% Pass rate | B4: 100% | C4: =IF(COUNTIFS('Test Cases'!D2:D160,"P0",'Test Cases'!F2:F160,"Failed")=0,"OK","BLOCKED")
A5: P1 con >=95% Pass rate | B5: >=95% | C5: =IF(IFERROR(COUNTIFS('Test Cases'!D2:D160,"P1",'Test Cases'!F2:F160,"Passed")/COUNTIF('Test Cases'!D2:D160,"P1"),0)>=0.95,"OK","REVIEW")
A6: P2 con >=80% ejecutados | B6: >=80% | C6: =IF(IFERROR((COUNTIFS('Test Cases'!D2:D160,"P2",'Test Cases'!F2:F160,"Passed")+COUNTIFS('Test Cases'!D2:D160,"P2",'Test Cases'!F2:F160,"Failed"))/COUNTIF('Test Cases'!D2:D160,"P2"),0)>=0.8,"OK","REVIEW")
A7: Sin defectos P0 abiertos | B7: 0 | C7: =IF(COUNTIFS('Defects Log'!C2:C200,"P0",'Defects Log'!K2:K200,"Open")=0,"OK","BLOCKED")
A8: Cobertura global >=90% | B8: >=90% | C8: =IF(Summary!B15>=0.9,"OK","REVIEW")
A9: PAR readiness funciona | B9: yes | C9: =IF(COUNTIFS('Test Cases'!A2:A300,"PAR-04",'Test Cases'!F2:F300,"Passed")>0,"OK","BLOCKED")
A10: HSS frequency descent OK | B10: yes | C10: =IF(COUNTIFS('Test Cases'!A2:A300,"HST-04",'Test Cases'!F2:F300,"Passed")>0,"OK","BLOCKED")
A11: Mic data privacy | B11: yes | C11: =IF(COUNTIFS('Test Cases'!A2:A300,"SEC-04",'Test Cases'!F2:F300,"Passed")>0,"OK","BLOCKED")
